Workbook

Sheet 鄉鎮市區房價
A1: 縣市 | B1: 鄉鎮市區 | C1: 大樓平均單價（萬元／坪） | D1: 近一年漲跌幅 | E1: 備註
A2: 台北市 | B2: 中正區 | C2: 127.51 | D2: 0.1267
A3: 台北市 | B3: 大同區 | C3: 102.86 | D3: 0.0032
A4: 台北市 | B4: 中山區 | C4: 109.54 | D4: 0.0822
A5: 台北市 | B5: 松山區 | C5: 115.6 | D5: 0.1083
A6: 台北市 | B6: 大安區 | C6: 139 | D6: 0.0543
A7: 台北市 | B7: 萬華區 | C7: 85.55 | D7: 0.061
A8: 台北市 | B8: 信義區 | C8: 116.98 | D8: 0.0308
A9: 台北市 | B9: 士林區 | C9: 96.93 | D9: 0.0468
A10: 台北市 | B10: 北投區 | C10: 99.18 | D10: 0.0869
A11: 台北市 | B11: 內湖區 | C11: 85.65 | D11: -0.0132
A12: 台北市 | B12: 南港區 | C12: 115.19 | D12: 0.0392
A13: 台北市 | B13: 文山區 | C13: 92.96 | D13: 0.0576
... A27: 新北市 | B27: 瑞芳區 | C27: 25.04 | D27: 0.3228
A28: 新北市 | B28: 平溪區 | C28: -- | D28: -- | E28: 資料極少
A29: 新北市 | B29: 雙溪區 | C29: -- | D29: -- | E29: 資料極少
A30: 新北市 | B30: 貢寮區 | C30: 10.07 | D30: 0
A31: 新北市 | B31: 新店區 | C31: 69.24 | D31: 0.0987
A32: 新北市 | B32: 坪林區 | C32: -- | D32: -- | E32: 資料極少
A33: 新北市 | B33: 烏來區 | C33: -- | D33: -- | E33: 資料極少
A34: 新北市 | B34: 永和區 | C34: 80.98 | D34: 0.0672
A35: 新北市 | B35: 中和區 | C35: 70.03 | D35: 0.0091
A36: 新北市 | B36: 土城區 | C36: 59.84 | D36: 0.0045
A37: 新北市 | B37: 三峽區 | C37: 44.47 | D37: 0.0432
A38: 新北市 | B38: 樹林區 | C38: 44.63 | D38: 0.0178
A39: 新北市 | B39: 鶯歌區 | C39: 43.45 | D39: 0.0736
A40: 新北市 | B40: 三重區 | C40: 73.59 | D40: 0.0328
A41: 新北市 | B41: 新莊區 | C41: 62.87 | D41: 0.0363
A42: 新北市 | B42: 泰山區 | C42: 56.16 | D42: 0.0697
A43: 新北市 | B43: 林口區 | C43: 55.97 | D43: -0.0137
A44: 新北市 | B44: 蘆洲區 | C44: 62.71 | D44: 0.0925
A45: 新北市 | B45: 五股區 | C45: 44.06 | D45: -0.0302
... A59: 桃園市 | B59: 大溪區 | C59: 26.94 | D59: 0.1469
A60: 桃園市 | B60: 復興區 | C60: -- | D60: -- | E60: 資料極少
A61: 桃園市 | B61: 大園區 | C61: 37.49 | D61: 0.0221
A62: 桃園市 | B62: 蘆竹區 | C62: 37.81 | D62: 0.0037
A63: 新竹市 | B63: 東區 | C63: 58.47 | D63: 0.0911
A64: 新竹市 | B64: 北區 | C64: 41.86 | D64: -0.0447
A65: 新竹市 | B65: 香山區 | C65: 43.11 | D65: 0.1545
A66: 新竹縣 | B66: 竹北市 | C66: 63.05 | D66: 0.1093
...

Sheet 排序
A1: 縣市 | B1: 鄉鎮市區 | C1: 近一年成交均價(萬／坪) | D1: 近一年漲跌幅 | E1: 備註
A2: 新北市 | B2: 平溪區 | C2: -- | D2: -- | E2: 資料極少
A3: 新北市 | B3: 雙溪區 | C3: -- | D3: -- | E3: 資料極少
A4: 新北市 | B4: 坪林區 | C4: -- | D4: -- | E4: 資料極少
A5: 新北市 | B5: 烏來區 | C5: -- | D5: -- | E5: 資料極少
A6: 桃園市 | B6: 復興區 | C6: -- | D6: -- | E6: 資料極少
A7: 新竹縣 | B7: 五峰鄉 | C7: -- | D7: -- | E7: 資料極少
A8: 新竹縣 | B8: 尖石鄉 | C8: -- | D8: -- | E8: 資料極少
A9: 苗栗縣 | B9: 三灣鄉 | C9: -- | D9: -- | E9: 資料極少
A10: 苗栗縣 | B10: 南庄鄉 | C10: -- | D10: -- | E10: 資料極少
A11: 苗栗縣 | B11: 獅潭鄉 | C11: -- | D11: -- | E11: 資料極少
A12: 苗栗縣 | B12: 通霄鎮 | C12: -- | D12: -- | E12: 資料極少
... A116: 連江縣 | B116: 東引鄉 | C116: -- | D116: -- | E116: 資料極少
A117: 台北市 | B117: 大安區 | C117: 139 | D117: 0.0543
A118: 台北市 | B118: 中正區 | C118: 127.51 | D118: 0.1267
A119: 台北市 | B119: 信義區 | C119: 116.98 | D119: 0.0308
A120: 台北市 | B120: 松山區 | C120: 115.6 | D120: 0.1083
A121: 台北市 | B121: 南港區 | C121: 115.19 | D121: 0.0392
A122: 台北市 | B122: 中山區 | C122: 109.54 | D122: 0.0822
A123: 台北市 | B123: 大同區 | C123: 102.86 | D123: 0.0032
A124: 台北市 | B124: 北投區 | C124: 99.18 | D124: 0.0869
A125: 台北市 | B125: 士林區 | C125: 96.93 | D125: 0.0468
A126: 台北市 | B126: 文山區 | C126: 92.96 | D126: 0.0576
A127: 台北市 | B127: 內湖區 | C127: 85.65 | D127: -0.0132
A128: 台北市 | B128: 萬華區 | C128: 85.55 | D128: 0.061
... A369: 新北市 | B369: 石門區 | C369: 3.05 | D369: -0.0224

Sheet 縣市房價
A1: 縣市 | B1: 近一年成交均價(萬/坪) | C1: 近一年漲跌幅 | D1: 鄉鎮市區數 | E1: 有價格資料數 | F1: 備註
A2: 台北市 | B2: 107.62 | C2: 0.0575 | D2: =COUNTIF('鄉鎮市區房價'!A$2:A$400,A2) -> 12 | E2: =COUNTIFS('鄉鎮市區房價'!A$2:A$400,A2,'鄉鎮市區房價'!C$2:C$400,">0") -> 12
A3: 基隆市 | B3: 29.21 | C3: -0.0142 | D3: =COUNTIF('鄉鎮市區房價'!A$2:A$400,A3) -> 7 | E3: =COUNTIFS('鄉鎮市區房價'!A$2:A$400,A3,'鄉鎮市區房價'!C$2:C$400,">0") -> 7
A4: 新北市 | B4: 60.34 | C4: 0.0538 | D4: =COUNTIF('鄉鎮市區房價'!A$2:A$400,A4) -> 29 | E4: =COUNTIFS('鄉鎮市區房價'!A$2:A$400,A4,'鄉鎮市區房價'!C$2:C$400,">0") -> 25
A5: 桃園市 | B5: 38.64 | C5: 0.0274 | D5: =COUNTIF('鄉鎮市區房價'!A$2:A$400,A5) -> 13 | E5: =COUNTIFS('鄉鎮市區房價'!A$2:A$400,A5,'鄉鎮市區房價'!C$2:C$400,">0") -> 12
A6: 新竹市 | B6: 50.88 | C6: 0.0678 | D6: =COUNTIF('鄉鎮市區房價'!A$2:A$400,A6) -> 3 | E6: =COUNTIFS('鄉鎮市區房價'!A$2:A$400,A6,'鄉鎮市區房價'!C$2:C$400,">0") -> 3
A7: 新竹縣 | B7: 51.58 | C7: 0.1157 | D7: =COUNTIF('鄉鎮市區房價'!A$2:A$400,A7) -> 13 | E7: =COUNTIFS('鄉鎮市區房價'!A$2:A$400,A7,'鄉鎮市區房價'!C$2:C$400,">0") -> 11
A8: 苗栗縣 | B8: 30.8 | C8: -0.0781 | D8: =COUNTIF('鄉鎮市區房價'!A$2:A$400,A8) -> 18 | E8: =COUNTIFS('鄉鎮市區房價'!A$2:A$400,A8,'鄉鎮市區房價'!C$2:C$400,">0") -> 8
A9: 台中市 | B9: 40.87 | C9: -0.0368 | D9: =COUNTIF('鄉鎮市區房價'!A$2:A$400,A9) -> 29 | E9: =COUNTIFS('鄉鎮市區房價'!A$2:A$400,A9,'鄉鎮市區房價'!C$2:C$400,">0") -> 27
A10: 彰化縣 | B10: 28.66 | C10: 0.035 | D10: =COUNTIF('鄉鎮市區房價'!A$2:A$400,A10) -> 26 | E10: =COUNTIFS('鄉鎮市區房價'!A$2:A$400,A10,'鄉鎮市區房價'!C$2:C$400,">0") -> 22
A11: 南投縣 | B11: 23.97 | C11: -0.0492 | D11: =COUNTIF('鄉鎮市區房價'!A$2:A$400,A11) -> 13 | E11: =COUNTIFS('鄉鎮市區房價'!A$2:A$400,A11,'鄉鎮市區房價'!C$2:C$400,">0") -> 8
A12: 雲林縣 | B12: 22.44 | C12: -0.0307 | D12: =COUNTIF('鄉鎮市區房價'!A$2:A$400,A12) -> 20 | E12: =COUNTIFS('鄉鎮市區房價'!A$2:A$400,A12,'鄉鎮市區房價'!C$2:C$400,">0") -> 8
A13: 嘉義市 | B13: 25.82 | C13: -0.0223 | D13: =COUNTIF('鄉鎮市區房價'!A$2:A$400,A13) -> 2 | E13: =COUNTIFS('鄉鎮市區房價'!A$2:A$400,A13,'鄉鎮市區房價'!C$2:C$400,">0") -> 2
... A20: 台東縣 | B20: 20.9 | C20: 0.0598 | D20: =COUNTIF('鄉鎮市區房價'!A$2:A$400,A20) -> 16 | E20: =COUNTIFS('鄉鎮市區房價'!A$2:A$400,A20,'鄉鎮市區房價'!C$2:C$400,">0") -> 4
A21: 澎湖縣 | B21: -- | C21: -- | D21: =COUNTIF('鄉鎮市區房價'!A$2:A$400,A21) -> 6 | E21: =COUNTIFS('鄉鎮市區房價'!A$2:A$400,A21,'鄉鎮市區房價'!C$2:C$400,">0") -> 0 | F21: 資料極少
A22: 金門縣 | B22: -- | C22: -- | D22: =COUNTIF('鄉鎮市區房價'!A$2:A$400,A22) -> 6 | E22: =COUNTIFS('鄉鎮市區房價'!A$2:A$400,A22,'鄉鎮市區房價'!C$2:C$400,">0") -> 0 | F22: 資料極少
A23: 連江縣 | B23: -- | C23: -- | D23: =COUNTIF('鄉鎮市區房價'!A$2:A$400,A23) -> 4 | E23: =COUNTIFS('鄉鎮市區房價'!A$2:A$400,A23,'鄉鎮市區房價'!C$2:C$400,">0") -> 0 | F23: 資料極少
A24: 合計 | D24: =SUM(D2:D23) -> 368 | E24: =SUM(E2:E23) -> 253

Sheet 說明
A1: 資料來源：樂居 房價地圖 https://www.leju.com.tw/map?mode=price
A2: 擷取日期：2026-09-30
A3: 價格定義：網站列表之「近一年」成交均價（萬元/坪），漲跌幅為網站標示之近一年房價漲幅。
A4: 網站註：大樓類型統計排除透天、公寓、工業宅、地上權宅、員工宅、一樓及特殊交易，成交價為扣除車位後之交易單價。
A5: 「資料極少」：網站未提供該區價格（成交筆數過少），價格及漲跌幅欄位以「--」表示。
